Workbook

Sheet BS_Form
A1: 貸借対照表
A2: ※ 単年度出力用。資産の部と負債・純資産の部を左右に分けて表示。
A4: 資産の部 | B4: 金額 | D4: 負債・純資産の部 | E4: 金額
A5: 資産の部 | D5: 負債の部
A6: 流動資産 | D6: 流動負債
A7: 現金及び預金 | B7: =BS_Map!D6 | D7: 買掛金 | E7: =BS_Map!D49
A8: 受取手形・売掛金 | B8: =BS_Map!D7 | D8: 短期借入金 | E8: =BS_Map!D50
A9: 電子記録債権 | B9: =BS_Map!D8 | D9: 1年内返済予定の長期借入金 | E9: =BS_Map!D51
A10: 有価証券 | B10: =BS_Map!D9 | D10: 未払金 | E10: =BS_Map!D52
A11: 商品及び製品 | B11: =BS_Map!D10 | D11: 未払費用 | E11: =BS_Map!D53
A12: 仕掛品 | B12: =BS_Map!D11 | D12: 未払法人税等 | E12: =BS_Map!D54
A13: 原材料及び貯蔵品 | B13: =BS_Map!D12 | D13: 契約負債 | E13: =BS_Map!D55
A14: 前払費用 | B14: =BS_Map!D13 | D14: 預り金 | E14: =BS_Map!D56
A15: 短期貸付金 | B15: =BS_Map!D14 | D15: 賞与引当金 | E15: =BS_Map!D57
A16: 未収収益 | B16: =BS_Map!D15 | D16: リース債務（流動） | E16: =BS_Map!D58
A17: その他の流動資産 | B17: =BS_Map!D16 | D17: その他の流動負債 | E17: =BS_Map!D59
A18: 貸倒引当金（流動） | B18: =BS_Map!D17 | D18: 流動負債合計 | E18: =BS_Map!D60
A19: 流動資産合計 | B19: =BS_Map!D18 | D19: 固定負債
A20: 固定資産 | D20: 社債 | E20: =BS_Map!D62
A21: 有形固定資産 | D21: 長期借入金 | E21: =BS_Map!D63
A22: 建物及び構築物 | B22: =BS_Map!D21 | D22: 長期未払金 | E22: =BS_Map!D64
A23: 機械装置及び車両運搬具 | B23: =BS_Map!D22 | D23: リース債務（固定） | E23: =BS_Map!D65
A24: 工具器具備品 | B24: =BS_Map!D23 | D24: 繰延税金負債 | E24: =BS_Map!D66
A25: 土地 | B25: =BS_Map!D24 | D25: 退職給付引当金 | E25: =BS_Map!D67
A26: リース資産 | B26: =BS_Map!D25 | D26: 資産除去債務 | E26: =BS_Map!D68
A27: 建設仮勘定 | B27: =BS_Map!D26 | D27: その他の固定負債 | E27: =BS_Map!D69
A28: 減価償却累計額 | B28: =BS_Map!D27 | D28: 固定負債合計 | E28: =BS_Map!D70
A29: 有形固定資産合計 | B29: =BS_Map!D28 | D29: 負債合計 | E29: =BS_Map!D71
A30: 無形固定資産 | D30: 純資産の部
A31: のれん | B31: =BS_Map!D30 | D31: 資本金 | E31: =BS_Map!D74
A32: ソフトウェア | B32: =BS_Map!D31 | D32: 資本剰余金 | E32: =BS_Map!D75
A33: その他の無形固定資産 | B33: =BS_Map!D32 | D33: 利益剰余金 | E33: =BS_Map!D76
A34: 無形固定資産合計 | B34: =BS_Map!D33 | D34: 自己株式 | E34: =BS_Map!D77
A35: 投資その他の資産 | D35: その他有価証券評価差額金 | E35: =BS_Map!D78
A36: 投資有価証券 | B36: =BS_Map!D35 | D36: 為替換算調整勘定 | E36: =BS_Map!D79
A37: 関係会社株式 | B37: =BS_Map!D36 | D37: 非支配株主持分 | E37: =BS_Map!D80
A38: 長期貸付金 | B38: =BS_Map!D37 | D38: 純資産合計 | E38: =BS_Map!D81
A39: 繰延税金資産 | B39: =BS_Map!D38 | D39: 負債純資産合計 | E39: =BS_Map!D82
A40: 差入保証金 | B40: =BS_Map!D39
A41: 退職給付資産 | B41: =BS_Map!D40
...

Sheet BS_Map
A1: B/S 中間集計（単年度）
A3: Kind | B3: 表示名 | C3: Line Item Key | D3: 当期末
A4: SECTION | B4: 資産
A5: SUBSECTION | B5: 流動資産
A6: DETAIL | B6: 現金及び預金 | C6: Cash and Deposits | D6: =SUMIFS(TB_Detail!$R$6:$R$101,TB_Detail!$C$6:$C$101,"BS",TB_Detail!$F$6:$F$101,C6)
A7: DETAIL | B7: 受取手形・売掛金 | C7: Notes and Accounts Receivable - Trade | D7: =SUMIFS(TB_Detail!$R$6:$R$101,TB_Detail!$C$6:$C$101,"BS",TB_Detail!$F$6:$F$101,C7)
A8: DETAIL | B8: 電子記録債権 | C8: Electronically Recorded Monetary Claims - Operating | D8: =SUMIFS(TB_Detail!$R$6:$R$101,TB_Detail!$C$6:$C$101,"BS",TB_Detail!$F$6:$F$101,C8)
A9: DETAIL | B9: 有価証券 | C9: Securities | D9: =SUMIFS(TB_Detail!$R$6:$R$101,TB_Detail!$C$6:$C$101,"BS",TB_Detail!$F$6:$F$101,C9)
A10: DETAIL | B10: 商品及び製品 | C10: Merchandise and Finished Goods | D10: =SUMIFS(TB_Detail!$R$6:$R$101,TB_Detail!$C$6:$C$101,"BS",TB_Detail!$F$6:$F$101,C10)
A11: DETAIL | B11: 仕掛品 | C11: Work in Process | D11: =SUMIFS(TB_Detail!$R$6:$R$101,TB_Detail!$C$6:$C$101,"BS",TB_Detail!$F$6:$F$101,C11)
A12: DETAIL | B12: 原材料及び貯蔵品 | C12: Raw Materials and Supplies | D12: =SUMIFS(TB_Detail!$R$6:$R$101,TB_Detail!$C$6:$C$101,"BS",TB_Detail!$F$6:$F$101,C12)
A13: DETAIL | B13: 前払費用 | C13: Prepaid Expenses | D13: =SUMIFS(TB_Detail!$R$6:$R$101,TB_Detail!$C$6:$C$101,"BS",TB_Detail!$F$6:$F$101,C13)
A14: DETAIL | B14: 短期貸付金 | C14: Short-term Loans Receivable | D14: =SUMIFS(TB_Detail!$R$6:$R$101,TB_Detail!$C$6:$C$101,"BS",TB_Detail!$F$6:$F$101,C14)
A15: DETAIL | B15: 未収収益 | C15: Accrued Income | D15: =SUMIFS(TB_Detail!$R$6:$R$101,TB_Detail!$C$6:$C$101,"BS",TB_Detail!$F$6:$F$101,C15)
A16: DETAIL | B16: その他の流動資産 | C16: Other Current Assets | D16: =SUMIFS(TB_Detail!$R$6:$R$101,TB_Detail!$C$6:$C$101,"BS",TB_Detail!$F$6:$F$101,C16)
A17: DETAIL | B17: 貸倒引当金（流動） | C17: Allowance for Doubtful Accounts (Current) | D17: =SUMIFS(TB_Detail!$R$6:$R$101,TB_Detail!$C$6:$C$101,"BS",TB_Detail!$F$6:$F$101,C17)
A18: TOTAL | B18: 流動資産合計 | D18: =SUM(D6:D17)
A19: SUBSECTION | B19: 固定資産
A20: MINOR | B20: 有形固定資産
A21: DETAIL | B21: 建物及び構築物 | C21: Buildings and Structures | D21: =SUMIFS(TB_Detail!$R$6:$R$101,TB_Detail!$C$6:$C$101,"BS",TB_Detail!$F$6:$F$101,C21)
A22: DETAIL | B22: 機械装置及び車両運搬具 | C22: Machinery, Equipment and Vehicles | D22: =SUMIFS(TB_Detail!$R$6:$R$101,TB_Detail!$C$6:$C$101,"BS",TB_Detail!$F$6:$F$101,C22)
A23: DETAIL | B23: 工具器具備品 | C23: Tools, Furniture and Fixtures | D23: =SUMIFS(TB_Detail!$R$6:$R$101,TB_Detail!$C$6:$C$101,"BS",TB_Detail!$F$6:$F$101,C23)
A24: DETAIL | B24: 土地 | C24: Land | D24: =SUMIFS(TB_Detail!$R$6:$R$101,TB_Detail!$C$6:$C$101,"BS",TB_Detail!$F$6:$F$101,C24)
A25: DETAIL | B25: リース資産 | C25: Leased Assets | D25: =SUMIFS(TB_Detail!$R$6:$R$101,TB_Detail!$C$6:$C$101,"BS",TB_Detail!$F$6:$F$101,C25)
A26: DETAIL | B26: 建設仮勘定 | C26: Construction in Progress | D26: =SUMIFS(TB_Detail!$R$6:$R$101,TB_Detail!$C$6:$C$101,"BS",TB_Detail!$F$6:$F$101,C26)
A27: DETAIL | B27: 減価償却累計額 | C27: Accumulated Depreciation | D27: =SUMIFS(TB_Detail!$R$6:$R$101,TB_Detail!$C$6:$C$101,"BS",TB_Detail!$F$6:$F$101,C27)
A28: TOTAL | B28: 有形固定資産合計 | D28: =SUM(D21:D27)
A29: MINOR | B29: 無形固定資産
A30: DETAIL | B30: のれん | C30: Goodwill | D30: =SUMIFS(TB_Detail!$R$6:$R$101,TB_Detail!$C$6:$C$101,"BS",TB_Detail!$F$6:$F$101,C30)
A31: DETAIL | B31: ソフトウェア | C31: Software | D31: =SUMIFS(TB_Detail!$R$6:$R$101,TB_Detail!$C$6:$C$101,"BS",TB_Detail!$F$6:$F$101,C31)
A32: DETAIL | B32: その他の無形固定資産 | C32: Other Intangible Assets | D32: =SUMIFS(TB_Detail!$R$6:$R$101,TB_Detail!$C$6:$C$101,"BS",TB_Detail!$F$6:$F$101,C32)
A33: TOTAL | B33: 無形固定資産合計 | D33: =SUM(D30:D32)
A34: MINOR | B34: 投資その他の資産
A35: DETAIL | B35: 投資有価証券 | C35: Investment Securities | D35: =SUMIFS(TB_Detail!$R$6:$R$101,TB_Detail!$C$6:$C$101,"BS",TB_Detail!$F$6:$F$101,C35)
A36: DETAIL | B36: 関係会社株式 | C36: Shares of Subsidiaries and Associates | D36: =SUMIFS(TB_Detail!$R$6:$R$101,TB_Detail!$C$6:$C$101,"BS",TB_Detail!$F$6:$F$101,C36)
A37: DETAIL | B37: 長期貸付金 | C37: Long-term Loans Receivable | D37: =SUMIFS(TB_Detail!$R$6:$R$101,TB_Detail!$C$6:$C$101,"BS",TB_Detail!$F$6:$F$101,C37)
A38: DETAIL | B38: 繰延税金資産 | C38: Deferred Tax Assets | D38: =SUMIFS(TB_Detail!$R$6:$R$101,TB_Detail!$C$6:$C$101,"BS",TB_Detail!$F$6:$F$101,C38)
A39: DETAIL | B39: 差入保証金 | C39: Guarantee Deposits | D39: =SUMIFS(TB_Detail!$R$6:$R$101,TB_Detail!$C$6:$C$101,"BS",TB_Detail!$F$6:$F$101,C39)
A40: DETAIL | B40: 退職給付資産 | C40: Retirement Benefit Asset | D40: =SUMIFS(TB_Detail!$R$6:$R$101,TB_Detail!$C$6:$C$101,"BS",TB_Detail!$F$6:$F$101,C40)
A41: DETAIL | B41: その他の投資その他の資産 | C41: Other Investments and Other Assets | D41: =SUMIFS(TB_Detail!$R$6:$R$101,TB_Detail!$C$6:$C$101,"BS",TB_Detail!$F$6:$F$101,C41)
...

Sheet TB_Detail
A1: 試算表詳細（前期 / 当期）
A3: 説明 | B3: COA_Masterの開始残高とJournal_Inputの仕訳から、前期/当期の試算表・B/S・P/Lを自動算出します。
A5: Code | B5: 勘定科目名 | C5: FS | D5: 大区分 | E5: 中区分 | F5: 表示行 | G5: Normal | H5: Display_Sign | I5: 前期開始 | J5: 前期借方 | K5: 前期貸方 | L5: 前期末 | M5: 当期開始 | N5: 当期借方 | O5: 当期貸方 | P5: 当期末 | Q5: 前期表示額 | R5: 当期表示額 | S5: CF_Class | T5: Analysis_Tag | U5: Notes
A6: =COA_Master!A5 | B6: =COA_Master!B5 | C6: =COA_Master!D5 | D6: =COA_Master!E5 | E6: =COA_Master!F5 | F6: =COA_Master!G5 | G6: =COA_Master!H5 | H6: =COA_Master!I5 | I6: =COA_Master!M5 | J6: =SUMIFS(Journal_Input!$K$8:$K$184,Journal_Input!$A$8:$A$184,"Prior",Journal_Input!$G$8:$G$184,A6) | K6: =SUMIFS(Journal_Input!$K$8:$K$184,Journal_Input!$A$8:$A$184,"Prior",Journal_Input!$I$8:$I$184,A6) | L6: =IF(G6="Dr",I6+J6-K6,I6-J6+K6) | M6: =L6 | N6: =SUMIFS(Journal_Input!$K$8:$K$184,Journal_Input!$A$8:$A$184,"Current",Journal_Input!$G$8:$G$184,A6) | O6: =SUMIFS(Journal_Input!$K$8:$K$184,Journal_Input!$A$8:$A$184,"Current",Journal_Input!$I$8:$I$184,A6) | P6: =IF(G6="Dr",M6+N6-O6,M6-N6+O6) | Q6: =IF(C6="BS",L6*H6,IF(G6="Dr",(J6-K6)*H6,(K6-J6)*H6)) | R6: =IF(C6="BS",P6*H6,IF(G6="Dr",(N6-O6)*H6,(O6-N6)*H6)) | S6: =COA_Master!K5 | T6: =COA_Master!L5 | U6: =COA_Master!N5
A7: =COA_Master!A6 | B7: =COA_Master!B6 | C7: =COA_Master!D6 | D7: =COA_Master!E6 | E7: =COA_Master!F6 | F7: =COA_Master!G6 | G7: =COA_Master!H6 | H7: =COA_Master!I6 | I7: =COA_Master!M6 | J7: =SUMIFS(Journal_Input!$K$8:$K$184,Journal_Input!$A$8:$A$184,"Prior",Journal_Input!$G$8:$G$184,A7) | K7: =SUMIFS(Journal_Input!$K$8:$K$184,Journal_Input!$A$8:$A$184,"Prior",Journal_Input!$I$8:$I$184,A7) | L7: =IF(G7="Dr",I7+J7-K7,I7-J7+K7) | M7: =L7 | N7: =SUMIFS(Journal_Input!$K$8:$K$184,Journal_Input!$A$8:$A$184,"Current",Journal_Input!$G$8:$G$184,A7) | O7: =SUMIFS(Journal_Input!$K$8:$K$184,Journal_Input!$A$8:$A$184,"Current",Journal_Input!$I$8:$I$184,A7) | P7: =IF(G7="Dr",M7+N7-O7,M7-N7+O7) | Q7: =IF(C7="BS",L7*H7,IF(G7="Dr",(J7-K7)*H7,(K7-J7)*H7)) | R7: =IF(C7="BS",P7*H7,IF(G7="Dr",(N7-O7)*H7,(O7-N7)*H7)) | S7: =COA_Master!K6 | T7: =COA_Master!L6 | U7: =COA_Master!N6
A8: =COA_Master!A7 | B8: =COA_Master!B7 | C8: =COA_Master!D7 | D8: =COA_Master!E7 | E8: =COA_Master!F7 | F8: =COA_Master!G7 | G8: =COA_Master!H7 | H8: =COA_Master!I7 | I8: =COA_Master!M7 | J8: =SUMIFS(Journal_Input!$K$8:$K$184,Journal_Input!$A$8:$A$184,"Prior",Journal_Input!$G$8:$G$184,A8) | K8: =SUMIFS(Journal_Input!$K$8:$K$184,Journal_Input!$A$8:$A$184,"Prior",Journal_Input!$I$8:$I$184,A8) | L8: =IF(G8="Dr",I8+J8-K8,I8-J8+K8) | M8: =L8 | N8: =SUMIFS(Journal_Input!$K$8:$K$184,Journal_Input!$A$8:$A$184,"Current",Journal_Input!$G$8:$G$184,A8) | O8: =SUMIFS(Journal_Input!$K$8:$K$184,Journal_Input!$A$8:$A$184,"Current",Journal_Input!$I$8:$I$184,A8) | P8: =IF(G8="Dr",M8+N8-O8,M8-N8+O8) | Q8: =IF(C8="BS",L8*H8,IF(G8="Dr",(J8-K8)*H8,(K8-J8)*H8)) | R8: =IF(C8="BS",P8*H8,IF(G8="Dr",(N8-O8)*H8,(O8-N8)*H8)) | S8: =COA_Master!K7 | T8: =COA_Master!L7 | U8: =COA_Master!N7
A9: =COA_Master!A8 | B9: =COA_Master!B8 | C9: =COA_Master!D8 | D9: =COA_Master!E8 | E9: =COA_Master!F8 | F9: =COA_Master!G8 | G9: =COA_Master!H8 | H9: =COA_Master!I8 | I9: =COA_Master!M8 | J9: =SUMIFS(Journal_Input!$K$8:$K$184,Journal_Input!$A$8:$A$184,"Prior",Journal_Input!$G$8:$G$184,A9) | K9: =SUMIFS(Journal_Input!$K$8:$K$184,Journal_Input!$A$8:$A$184,"Prior",Journal_Input!$I$8:$I$184,A9) | L9: =IF(G9="Dr",I9+J9-K9,I9-J9+K9) | M9: =L9 | N9: =SUMIFS(Journal_Input!$K$8:$K$184,Journal_Input!$A$8:$A$184,"Current",Journal_Input!$G$8:$G$184,A9) | O9: =SUMIFS(Journal_Input!$K$8:$K$184,Journal_Input!$A$8:$A$184,"Current",Journal_Input!$I$8:$I$184,A9) | P9: =IF(G9="Dr",M9+N9-O9,M9-N9+O9) | Q9: =IF(C9="BS",L9*H9,IF(G9="Dr",(J9-K9)*H9,(K9-J9)*H9)) | R9: =IF(C9="BS",P9*H9,IF(G9="Dr",(N9-O9)*H9,(O9-N9)*H9)) | S9: =COA_Master!K8 | T9: =COA_Master!L8 | U9: =COA_Master!N8
A10: =COA_Master!A9 | B10: =COA_Master!B9 | C10: =COA_Master!D9 | D10: =COA_Master!E9 | E10: =COA_Master!F9 | F10: =COA_Master!G9 | G10: =COA_Master!H9 | H10: =COA_Master!I9 | I10: =COA_Master!M9 | J10: =SUMIFS(Journal_Input!$K$8:$K$184,Journal_Input!$A$8:$A$184,"Prior",Journal_Input!$G$8:$G$184,A10) | K10: =SUMIFS(Journal_Input!$K$8:$K$184,Journal_Input!$A$8:$A$184,"Prior",Journal_Input!$I$8:$I$184,A10) | L10: =IF(G10="Dr",I10+J10-K10,I10-J10+K10) | M10: =L10 | N10: =SUMIFS(Journal_Input!$K$8:$K$184,Journal_Input!$A$8:$A$184,"Current",Journal_Input!$G$8:$G$184,A10) | O10: =SUMIFS(Journal_Input!$K$8:$K$184,Journal_Input!$A$8:$A$184,"Current",Journal_Input!$I$8:$I$184,A10) | P10: =IF(G10="Dr",M10+N10-O10,M10-N10+O10) | Q10: =IF(C10="BS",L10*H10,IF(G10="Dr",(J10-K10)*H10,(K10-J10)*H10)) | R10: =IF(C10="BS",P10*H10,IF(G10="Dr",(N10-O10)*H10,(O10-N10)*H10)) | S10: =COA_Master!K9 | T10: =COA_Master!L9 | U10: =COA_Master!N9
A11: =COA_Master!A10 | B11: =COA_Master!B10 | C11: =COA_Master!D10 | D11: =COA_Master!E10 | E11: =COA_Master!F10 | F11: =COA_Master!G10 | G11: =COA_Master!H10 | H11: =COA_Master!I10 | I11: =COA_Master!M10 | J11: =SUMIFS(Journal_Input!$K$8:$K$184,Journal_Input!$A$8:$A$184,"Prior",Journal_Input!$G$8:$G$184,A11) | K11: =SUMIFS(Journal_Input!$K$8:$K$184,Journal_Input!$A$8:$A$184,"Prior",Journal_Input!$I$8:$I$184,A11) | L11: =IF(G11="Dr",I11+J11-K11,I11-J11+K11) | M11: =L11 | N11: =SUMIFS(Journal_Input!$K$8:$K$184,Journal_Input!$A$8:$A$184,"Current",Journal_Input!$G$8:$G$184,A11) | O11: =SUMIFS(Journal_Input!$K$8:$K$184,Journal_Input!$A$8:$A$184,"Current",Journal_Input!$I$8:$I$184,A11) | P11: =IF(G11="Dr",M11+N11-O11,M11-N11+O11) | Q11: =IF(C11="BS",L11*H11,IF(G11="Dr",(J11-K11)*H11,(K11-J11)*H11)) | R11: =IF(C11="BS",P11*H11,IF(G11="Dr",(N11-O11)*H11,(O11-N11)*H11)) | S11: =COA_Master!K10 | T11: =COA_Master!L10 | U11: =COA_Master!N10
A12: =COA_Master!A11 | B12: =COA_Master!B11 | C12: =COA_Master!D11 | D12: =COA_Master!E11 | E12: =COA_Master!F11 | F12: =COA_Master!G11 | G12: =COA_Master!H11 | H12: =COA_Master!I11 | I12: =COA_Master!M11 | J12: =SUMIFS(Journal_Input!$K$8:$K$184,Journal_Input!$A$8:$A$184,"Prior",Journal_Input!$G$8:$G$184,A12) | K12: =SUMIFS(Journal_Input!$K$8:$K$184,Journal_Input!$A$8:$A$184,"Prior",Journal_Input!$I$8:$I$184,A12) | L12: =IF(G12="Dr",I12+J12-K12,I12-J12+K12) | M12: =L12 | N12: =SUMIFS(Journal_Input!$K$8:$K$184,Journal_Input!$A$8:$A$184,"Current",Journal_Input!$G$8:$G$184,A12) | O12: =SUMIFS(Journal_Input!$K$8:$K$184,Journal_Input!$A$8:$A$184,"Current",Journal_Input!$I$8:$I$184,A12) | P12: =IF(G12="Dr",M12+N12-O12,M12-N12+O12) | Q12: =IF(C12="BS",L12*H12,IF(G12="Dr",(J12-K12)*H12,(K12-J12)*H12)) | R12: =IF(C12="BS",P12*H12,IF(G12="Dr",(N12-O12)*H12,(O12-N12)*H12)) | S12: =COA_Master!K11 | T12: =COA_Master!L11 | U12: =COA_Master!N11
A13: =COA_Master!A12 | B13: =COA_Master!B12 | C13: =COA_Master!D12 | D13: =COA_Master!E12 | E13: =COA_Master!F12 | F13: =COA_Master!G12 | G13: =COA_Master!H12 | H13: =COA_Master!I12 | I13: =COA_Master!M12 | J13: =SUMIFS(Journal_Input!$K$8:$K$184,Journal_Input!$A$8:$A$184,"Prior",Journal_Input!$G$8:$G$184,A13) | K13: =SUMIFS(Journal_Input!$K$8:$K$184,Journal_Input!$A$8:$A$184,"Prior",Journal_Input!$I$8:$I$184,A13) | L13: =IF(G13="Dr",I13+J13-K13,I13-J13+K13) | M13: =L13 | N13: =SUMIFS(Journal_Input!$K$8:$K$184,Journal_Input!$A$8:$A$184,"Current",Journal_Input!$G$8:$G$184,A13) | O13: =SUMIFS(Journal_Input!$K$8:$K$184,Journal_Input!$A$8:$A$184,"Current",Journal_Input!$I$8:$I$184,A13) | P13: =IF(G13="Dr",M13+N13-O13,M13-N13+O13) | Q13: =IF(C13="BS",L13*H13,IF(G13="Dr",(J13-K13)*H13,(K13-J13)*H13)) | R13: =IF(C13="BS",P13*H13,IF(G13="Dr",(N13-O13)*H13,(O13-N13)*H13)) | S13: =COA_Master!K12 | T13: =COA_Master!L12 | U13: =COA_Master!N12
A14: =COA_Master!A13 | B14: =COA_Master!B13 | C14: =COA_Master!D13 | D14: =COA_Master!E13 | E14: =COA_Master!F13 | F14: =COA_Master!G13 | G14: =COA_Master!H13 | H14: =COA_Master!I13 | I14: =COA_Master!M13 | J14: =SUMIFS(Journal_Input!$K$8:$K$184,Journal_Input!$A$8:$A$184,"Prior",Journal_Input!$G$8:$G$184,A14) | K14: =SUMIFS(Journal_Input!$K$8:$K$184,Journal_Input!$A$8:$A$184,"Prior",Journal_Input!$I$8:$I$184,A14) | L14: =IF(G14="Dr",I14+J14-K14,I14-J14+K14) | M14: =L14 | N14: =SUMIFS(Journal_Input!$K$8:$K$184,Journal_Input!$A$8:$A$184,"Current",Journal_Input!$G$8:$G$184,A14) | O14: =SUMIFS(Journal_Input!$K$8:$K$184,Journal_Input!$A$8:$A$184,"Current",Journal_Input!$I$8:$I$184,A14) | P14: =IF(G14="Dr",M14+N14-O14,M14-N14+O14) | Q14: =IF(C14="BS",L14*H14,IF(G14="Dr",(J14-K14)*H14,(K14-J14)*H14)) | R14: =IF(C14="BS",P14*H14,IF(G14="Dr",(N14-O14)*H14,(O14-N14)*H14)) | S14: =COA_Master!K13 | T14: =COA_Master!L13 | U14: =COA_Master!N13
A15: =COA_Master!A14 | B15: =COA_Master!B14 | C15: =COA_Master!D14 | D15: =COA_Master!E14 | E15: =COA_Master!F14 | F15: =COA_Master!G14 | G15: =COA_Master!H14 | H15: =COA_Master!I14 | I15: =COA_Master!M14 | J15: =SUMIFS(Journal_Input!$K$8:$K$184,Journal_Input!$A$8:$A$184,"Prior",Journal_Input!$G$8:$G$184,A15) | K15: =SUMIFS(Journal_Input!$K$8:$K$184,Journal_Input!$A$8:$A$184,"Prior",Journal_Input!$I$8:$I$184,A15) | L15: =IF(G15="Dr",I15+J15-K15,I15-J15+K15) | M15: =L15 | N15: =SUMIFS(Journal_Input!$K$8:$K$184,Journal_Input!$A$8:$A$184,"Current",Journal_Input!$G$8:$G$184,A15) | O15: =SUMIFS(Journal_Input!$K$8:$K$184,Journal_Input!$A$8:$A$184,"Current",Journal_Input!$I$8:$I$184,A15) | P15: =IF(G15="Dr",M15+N15-O15,M15-N15+O15) | Q15: =IF(C15="BS",L15*H15,IF(G15="Dr",(J15-K15)*H15,(K15-J15)*H15)) | R15: =IF(C15="BS",P15*H15,IF(G15="Dr",(N15-O15)*H15,(O15-N15)*H15)) | S15: =COA_Master!K14 | T15: =COA_Master!L14 | U15: =COA_Master!N14
A16: =COA_Master!A15 | B16: =COA_Master!B15 | C16: =COA_Master!D15 | D16: =COA_Master!E15 | E16: =COA_Master!F15 | F16: =COA_Master!G15 | G16: =COA_Master!H15 | H16: =COA_Master!I15 | I16: =COA_Master!M15 | J16: =SUMIFS(Journal_Input!$K$8:$K$184,Journal_Input!$A$8:$A$184,"Prior",Journal_Input!$G$8:$G$184,A16) | K16: =SUMIFS(Journal_Input!$K$8:$K$184,Journal_Input!$A$8:$A$184,"Prior",Journal_Input!$I$8:$I$184,A16) | L16: =IF(G16="Dr",I16+J16-K16,I16-J16+K16) | M16: =L16 | N16: =SUMIFS(Journal_Input!$K$8:$K$184,Journal_Input!$A$8:$A$184,"Current",Journal_Input!$G$8:$G$184,A16) | O16: =SUMIFS(Journal_Input!$K$8:$K$184,Journal_Input!$A$8:$A$184,"Current",Journal_Input!$I$8:$I$184,A16) | P16: =IF(G16="Dr",M16+N16-O16,M16-N16+O16) | Q16: =IF(C16="BS",L16*H16,IF(G16="Dr",(J16-K16)*H16,(K16-J16)*H16)) | R16: =IF(C16="BS",P16*H16,IF(G16="Dr",(N16-O16)*H16,(O16-N16)*H16)) | S16: =COA_Master!K15 | T16: =COA_Master!L15 | U16: =COA_Master!N15
A17: =COA_Master!A16 | B17: =COA_Master!B16 | C17: =COA_Master!D16 | D17: =COA_Master!E16 | E17: =COA_Master!F16 | F17: =COA_Master!G16 | G17: =COA_Master!H16 | H17: =COA_Master!I16 | I17: =COA_Master!M16 | J17: =SUMIFS(Journal_Input!$K$8:$K$184,Journal_Input!$A$8:$A$184,"Prior",Journal_Input!$G$8:$G$184,A17) | K17: =SUMIFS(Journal_Input!$K$8:$K$184,Journal_Input!$A$8:$A$184,"Prior",Journal_Input!$I$8:$I$184,A17) | L17: =IF(G17="Dr",I17+J17-K17,I17-J17+K17) | M17: =L17 | N17: =SUMIFS(Journal_Input!$K$8:$K$184,Journal_Input!$A$8:$A$184,"Current",Journal_Input!$G$8:$G$184,A17) | O17: =SUMIFS(Journal_Input!$K$8:$K$184,Journal_Input!$A$8:$A$184,"Current",Journal_Input!$I$8:$I$184,A17) | P17: =IF(G17="Dr",M17+N17-O17,M17-N17+O17) | Q17: =IF(C17="BS",L17*H17,IF(G17="Dr",(J17-K17)*H17,(K17-J17)*H17)) | R17: =IF(C17="BS",P17*H17,IF(G17="Dr",(N17-O17)*H17,(O17-N17)*H17)) | S17: =COA_Master!K16 | T17: =COA_Master!L16 | U17: =COA_Master!N16
... A101: =COA_Master!A100 | B101: =COA_Master!B100 | C101: =COA_Master!D100 | D101: =COA_Master!E100 | E101: =COA_Master!F100 | F101: =COA_Master!G100 | G101: =COA_Master!H100 | H101: =COA_Master!I100 | I101: =COA_Master!M100 | J101: =SUMIFS(Journal_Input!$K$8:$K$184,Journal_Input!$A$8:$A$184,"Prior",Journal_Input!$G$8:$G$184,A101) | K101: =SUMIFS(Journal_Input!$K$8:$K$184,Journal_Input!$A$8:$A$184,"Prior",Journal_Input!$I$8:$I$184,A101) | L101: =IF(G101="Dr",I101+J101-K101,I101-J101+K101) | M101: =L101 | N101: =SUMIFS(Journal_Input!$K$8:$K$184,Journal_Input!$A$8:$A$184,"Current",Journal_Input!$G$8:$G$184,A101) | O101: =SUMIFS(Journal_Input!$K$8:$K$184,Journal_Input!$A$8:$A$184,"Current",Journal_Input!$I$8:$I$184,A101) | P101: =IF(G101="Dr",M101+N101-O101,M101-N101+O101) | Q101: =IF(C101="BS",L101*H101,IF(G101="Dr",(J101-K101)*H101,(K101-J101)*H101)) | R101: =IF(C101="BS",P101*H101,IF(G101="Dr",(N101-O101)*H101,(O101-N101)*H101)) | S101: =COA_Master!K100 | T101: =COA_Master!L100 | U101: =COA_Master!N100
A102: TOTAL | I102: =SUM(I6:I101) | J102: =SUM(J6:J101) | K102: =SUM(K6:K101) | L102: =SUM(L6:L101) | M102: =SUM(M6:M101) | N102: =SUM(N6:N101) | O102: =SUM(O6:O101) | P102: =SUM(P6:P101) | ... R102: =SUM(R6:R101)
A103: Check | B103: 前期借貸差額 | C103: =J102-K102
B104: 当期借貸差額 | C104: =N102-O102

Sheet COA_Master
A1: 勘定科目マスター（分析拡張版）
A4: Code | B4: 勘定科目名 | C4: Account Name | D4: FS_Type | E4: 大区分 | F4: 中区分 | G4: 表示行 | H4: Normal | I4: Display_Sign | J4: 流動固定 | K4: CF_Class | L4: Analysis_Tag | M4: 前期開始残高 | N4: Notes
A5: 1110 | B5: 現金及び預金 | C5: Cash and Deposits | D5: BS | E5: 資産 | F5: 流動資産 | G5: Cash and Deposits | H5: Dr | I5: 1 | J5: Current | K5: Cash | L5: Liquidity | M5: 35000000 | N5: 主要運転資金
A6: 1120 | B6: 売掛金 | C6: Accounts Receivable - Trade | D6: BS | E6: 資産 | F6: 流動資産 | G6: Notes and Accounts Receivable - Trade | H6: Dr | I6: 1 | J6: Current | K6: Operating | L6: Working Capital | M6: 18000000 | N6: 営業債権
A7: 1130 | B7: 電子記録債権 | C7: Electronically Recorded Monetary Claims - Operating | D7: BS | E7: 資産 | F7: 流動資産 | G7: Electronically Recorded Monetary Claims - Operating | H7: Dr | I7: 1 | J7: Current | K7: Operating | L7: Working Capital | M7: 0
A8: 1140 | B8: 有価証券 | C8: Securities | D8: BS | E8: 資産 | F8: 流動資産 | G8: Securities | H8: Dr | I8: 1 | J8: Current | K8: Investing | L8: Liquidity | M8: 0
A9: 1150 | B9: 商品及び製品 | C9: Merchandise and Finished Goods | D9: BS | E9: 資産 | F9: 流動資産 | G9: Merchandise and Finished Goods | H9: Dr | I9: 1 | J9: Current | K9: Operating | L9: Inventory | M9: 12000000 | N9: 在庫
A10: 1160 | B10: 仕掛品 | C10: Work in Process | D10: BS | E10: 資産 | F10: 流動資産 | G10: Work in Process | H10: Dr | I10: 1 | J10: Current | K10: Operating | L10: Inventory | M10: 0
A11: 1170 | B11: 原材料及び貯蔵品 | C11: Raw Materials and Supplies | D11: BS | E11: 資産 | F11: 流動資産 | G11: Raw Materials and Supplies | H11: Dr | I11: 1 | J11: Current | K11: Operating | L11: Inventory | M11: 0
A12: 1180 | B12: 前払費用 | C12: Prepaid Expenses | D12: BS | E12: 資産 | F12: 流動資産 | G12: Prepaid Expenses | H12: Dr | I12: 1 | J12: Current | K12: Operating | L12: Working Capital | M12: 1500000
A13: 1190 | B13: 短期貸付金 | C13: Short-term Loans Receivable | D13: BS | E13: 資産 | F13: 流動資産 | G13: Short-term Loans Receivable | H13: Dr | I13: 1 | J13: Current | K13: Investing | L13: Other Assets | M13: 0
A14: 1195 | B14: 未収収益 | C14: Accrued Income | D14: BS | E14: 資産 | F14: 流動資産 | G14: Accrued Income | H14: Dr | I14: 1 | J14: Current | K14: Operating | L14: Working Capital | M14: 0
A15: 1198 | B15: その他の流動資産 | C15: Other Current Assets | D15: BS | E15: 資産 | F15: 流動資産 | G15: Other Current Assets | H15: Dr | I15: 1 | J15: Current | K15: Operating | L15: Other Assets | M15: 0
A16: 1199 | B16: 貸倒引当金（流動） | C16: Allowance for Doubtful Accounts (Current) | D16: BS | E16: 資産 | F16: 流動資産 | G16: Allowance for Doubtful Accounts (Current) | H16: Cr | I16: -1 | J16: Current | K16: Non-cash | L16: Credit Risk | M16: 0 | N16: 控除科目
A17: 1510 | B17: 建物 | C17: Buildings and Structures | D17: BS | E17: 資産 | F17: 固定資産 | G17: Buildings and Structures | H17: Dr | I17: 1 | J17: Non-current | K17: Investing | L17: Fixed Assets | M17: 40000000
A18: 1520 | B18: 機械装置及び車両運搬具 | C18: Machinery, Equipment and Vehicles | D18: BS | E18: 資産 | F18: 固定資産 | G18: Machinery, Equipment and Vehicles | H18: Dr | I18: 1 | J18: Non-current | K18: Investing | L18: Fixed Assets | M18: 25000000
A19: 1530 | B19: 工具器具備品 | C19: Tools, Furniture and Fixtures | D19: BS | E19: 資産 | F19: 固定資産 | G19: Tools, Furniture and Fixtures | H19: Dr | I19: 1 | J19: Non-current | K19: Investing | L19: Fixed Assets | M19: 8000000
A20: 1540 | B20: 土地 | C20: Land | D20: BS | E20: 資産 | F20: 固定資産 | G20: Land | H20: Dr | I20: 1 | J20: Non-current | K20: Investing | L20: Fixed Assets | M20: 15000000
A21: 1550 | B21: リース資産 | C21: Leased Assets | D21: BS | E21: 資産 | F21: 固定資産 | G21: Leased Assets | H21: Dr | I21: 1 | J21: Non-current | K21: Investing | L21: Fixed Assets | M21: 0
A22: 1560 | B22: 建設仮勘定 | C22: Construction in Progress | D22: BS | E22: 資産 | F22: 固定資産 | G22: Construction in Progress | H22: Dr | I22: 1 | J22: Non-current | K22: Investing | L22: Fixed Assets | M22: 0
A23: 1590 | B23: 減価償却累計額 | C23: Accumulated Depreciation | D23: BS | E23: 資産 | F23: 固定資産 | G23: Accumulated Depreciation | H23: Cr | I23: -1 | J23: Non-current | K23: Non-cash | L23: Fixed Assets | M23: 30000000 | N23: 控除科目
A24: 1610 | B24: のれん | C24: Goodwill | D24: BS | E24: 資産 | F24: 固定資産 | G24: Goodwill | H24: Dr | I24: 1 | J24: Non-current | K24: Investing | L24: Intangibles | M24: 0
A25: 1620 | B25: ソフトウェア | C25: Software | D25: BS | E25: 資産 | F25: 固定資産 | G25: Software | H25: Dr | I25: 1 | J25: Non-current | K25: Investing | L25: Intangibles | M25: 3000000
A26: 1690 | B26: その他の無形固定資産 | C26: Other Intangible Assets | D26: BS | E26: 資産 | F26: 固定資産 | G26: Other Intangible Assets | H26: Dr | I26: 1 | J26: Non-current | K26: Investing | L26: Intangibles | M26: 0
A27: 1710 | B27: 投資有価証券 | C27: Investment Securities | D27: BS | E27: 資産 | F27: 固定資産 | G27: Investment Securities | H27: Dr | I27: 1 | J27: Non-current | K27: Investing | L27: Investments | M27: 0
A28: 1720 | B28: 関係会社株式 | C28: Shares of Subsidiaries and Associates | D28: BS | E28: 資産 | F28: 固定資産 | G28: Shares of Subsidiaries and Associates | H28: Dr | I28: 1 | J28: Non-current | K28: Investing | L28: Investments | M28: 0
A29: 1730 | B29: 長期貸付金 | C29: Long-term Loans Receivable | D29: BS | E29: 資産 | F29: 固定資産 | G29: Long-term Loans Receivable | H29: Dr | I29: 1 | J29: Non-current | K29: Investing | L29: Investments | M29: 0
A30: 1740 | B30: 繰延税金資産 | C30: Deferred Tax Assets | D30: BS | E30: 資産 | F30: 固定資産 | G30: Deferred Tax Assets | H30: Dr | I30: 1 | J30: Non-current | K30: Non-cash | L30: Tax | M30: 0
A31: 1750 | B31: 差入保証金 | C31: Guarantee Deposits | D31: BS | E31: 資産 | F31: 固定資産 | G31: Guarantee Deposits | H31: Dr | I31: 1 | J31: Non-current | K31: Investing | L31: Investments | M31: 0
A32: 1760 | B32: 退職給付資産 | C32: Retirement Benefit Asset | D32: BS | E32: 資産 | F32: 固定資産 | G32: Retirement Benefit Asset | H32: Dr | I32: 1 | J32: Non-current | K32: Non-cash | L32: Retirement | M32: 0
A33: 1798 | B33: その他の投資その他の資産 | C33: Other Investments and Other Assets | D33: BS | E33: 資産 | F33: 固定資産 | G33: Other Investments and Other Assets | H33: Dr | I33: 1 | J33: Non-current | K33: Investing | L33: Investments | M33: 0
A34: 1799 | B34: 貸倒引当金（固定） | C34: Allowance for Doubtful Accounts (Non-current) | D34: BS | E34: 資産 | F34: 固定資産 | G34: Allowance for Doubtful Accounts (Non-current) | H34: Cr | I34: -1 | J34: Non-current | K34: Non-cash | L34: Credit Risk | M34: 0 | N34: 控除科目
A35: 2110 | B35: 買掛金 | C35: Notes and Accounts Payable - Trade | D35: BS | E35: 負債 | F35: 流動負債 | G35: Notes and Accounts Payable - Trade | H35: Cr | I35: 1 | J35: Current | K35: Operating | L35: Working Capital | M35: 10000000 | N35: 営業債務
A36: 2120 | B36: 短期借入金 | C36: Short-term Borrowings | D36: BS | E36: 負債 | F36: 流動負債 | G36: Short-term Borrowings | H36: Cr | I36: 1 | J36: Current | K36: Financing | L36: Debt | M36: 5000000
A37: 2130 | B37: 1年内返済予定の長期借入金 | C37: Current Portion of Long-term Borrowings | D37: BS | E37: 負債 | F37: 流動負債 | G37: Current Portion of Long-term Borrowings | H37: Cr | I37: 1 | J37: Current | K37: Financing | L37: Debt | M37: 3000000
A38: 2140 | B38: 未払金 | C38: Accounts Payable - Other | D38: BS | E38: 負債 | F38: 流動負債 | G38: Accounts Payable - Other | H38: Cr | I38: 1 | J38: Current | K38: Operating | L38: Working Capital | M38: 0
A39: 2150 | B39: 未払費用 | C39: Accrued Expenses | D39: BS | E39: 負債 | F39: 流動負債 | G39: Accrued Expenses | H39: Cr | I39: 1 | J39: Current | K39: Operating | L39: Working Capital | M39: 2000000
A40: 2160 | B40: 未払法人税等 | C40: Income Taxes Payable | D40: BS | E40: 負債 | F40: 流動負債 | G40: Income Taxes Payable | H40: Cr | I40: 1 | J40: Current | K40: Operating | L40: Tax | M40: 1500000
A41: 2170 | B41: 契約負債 | C41: Contract Liabilities | D41: BS | E41: 負債 | F41: 流動負債 | G41: Contract Liabilities | H41: Cr | I41: 1 | J41: Current | K41: Operating | L41: Working Capital | M41: 0
A42: 2180 | B42: 預り金 | C42: Deposits Received | D42: BS | E42: 負債 | F42: 流動負債 | G42: Deposits Received | H42: Cr | I42: 1 | J42: Current | K42: Operating | L42: Working Capital | M42: 0
...

Sheet Journal_Input
A1: 仕訳入力（複式簿記）
A3: 入力ルール | B3: 1行 = 1仕訳（借方1科目 / 貸方1科目）。必要に応じて部門・セグメント・PJを入力。
A4: 期間区分 | B4: Prior / Current のみ入力
A5: 金額 | B5: 正数のみ入力
A7: Period | B7: Date | C7: Voucher No | D7: Department | E7: Segment | F7: Project | G7: Debit Code | H7: Debit Name | I7: Credit Code | J7: Credit Name | K7: Amount | L7: Description | M7: Counterparty | N7: Tax Code | O7: Invoice Flag | P7: Notes | Q7: Check
A8: Prior | B8: 2025/01/15 | C8: JV-25001 | D8: 営業部 | E8: 製品A | F8: PJ-A | G8: 1120 | H8: 売掛金 | I8: 4110 | J8: 売上高 | K8: 30000000 | L8: 掛売上 | M8: 得意先A | N8: 課税10% | O8: 適格 | Q8: =IF(AND(A8<>"",G8<>"",I8<>"",K8>0),"OK","")
A9: Prior | B9: 2025/01/18 | C9: JV-25002 | D9: 営業部 | E9: 製品A | F9: PJ-A | G9: 1110 | H9: 現金及び預金 | I9: 4110 | J9: 売上高 | K9: 12000000 | L9: 現金売上 | M9: 店舗売上 | N9: 課税10% | O9: 帳簿保存 | Q9: =IF(AND(A9<>"",G9<>"",I9<>"",K9>0),"OK","")
A10: Prior | B10: 2025/01/25 | C10: JV-25003 | D10: 営業部 | E10: 製品A | F10: PJ-A | G10: 1110 | H10: 現金及び預金 | I10: 1120 | J10: 売掛金 | K10: 25000000 | L10: 売掛回収 | M10: 得意先A | N10: 対象外 | O10: - | Q10: =IF(AND(A10<>"",G10<>"",I10<>"",K10>0),"OK","")
A11: Prior | B11: 2025/02/05 | C11: JV-25004 | D11: 購買部 | E11: 製品A | F11: PJ-A | G11: 5110 | H11: 売上原価 | I11: 2110 | J11: 買掛金 | K11: 18000000 | L11: 仕入計上 | M11: 仕入先A | N11: 課税10% | O11: 適格 | Q11: =IF(AND(A11<>"",G11<>"",I11<>"",K11>0),"OK","")
A12: Prior | B12: 2025/02/20 | C12: JV-25005 | D12: 購買部 | E12: 製品A | F12: PJ-A | G12: 2110 | H12: 買掛金 | I12: 1110 | J12: 現金及び預金 | K12: 15000000 | L12: 買掛支払 | M12: 仕入先A | N12: 対象外 | O12: - | Q12: =IF(AND(A12<>"",G12<>"",I12<>"",K12>0),"OK","")
A13: Prior | B13: 2025/03/25 | C13: JV-25006 | D13: 管理部 | E13: 共通 | F13: ADM | G13: 6120 | H13: 給料手当 | I13: 1110 | J13: 現金及び預金 | K13: 6000000 | L13: 給与支払 | M13: 従業員 | N13: 対象外 | O13: - | Q13: =IF(AND(A13<>"",G13<>"",I13<>"",K13>0),"OK","")
A14: Prior | B14: 2025/03/31 | C14: JV-25007 | D14: 管理部 | E14: 共通 | F14: ADM | G14: 6130 | H14: 賞与 | I14: 2190 | J14: 賞与引当金 | K14: 800000 | L14: 賞与引当 | M14: 従業員 | N14: 対象外 | O14: - | Q14: =IF(AND(A14<>"",G14<>"",I14<>"",K14>0),"OK","")
A15: Prior | B15: 2025/04/05 | C15: JV-25008 | D15: 営業部 | E15: 共通 | F15: SAL | G15: 6140 | H15: 福利厚生費 | I15: 1110 | J15: 現金及び預金 | K15: 700000 | L15: 福利厚生費支払 | M15: 福利厚生業者 | N15: 課税10% | O15: 適格 | Q15: =IF(AND(A15<>"",G15<>"",I15<>"",K15>0),"OK","")
A16: Prior | B16: 2025/04/12 | C16: JV-25009 | D16: 営業部 | E16: 共通 | F16: SAL | G16: 6160 | H16: 広告宣伝費 | I16: 1110 | J16: 現金及び預金 | K16: 900000 | L16: 広告費支払 | M16: 広告代理店 | N16: 課税10% | O16: 適格 | Q16: =IF(AND(A16<>"",G16<>"",I16<>"",K16>0),"OK","")
A17: Prior | B17: 2025/04/20 | C17: JV-25010 | D17: 営業部 | E17: 共通 | F17: SAL | G17: 6180 | H17: 旅費交通費 | I17: 1110 | J17: 現金及び預金 | K17: 650000 | L17: 出張旅費 | M17: 社員出張 | N17: 対象外 | O17: 帳簿保存 | Q17: =IF(AND(A17<>"",G17<>"",I17<>"",K17>0),"OK","")
A18: Prior | B18: 2025/05/10 | C18: JV-25011 | D18: 管理部 | E18: 共通 | F18: ADM | G18: 6190 | H18: 通信費 | I18: 1110 | J18: 現金及び預金 | K18: 300000 | L18: 通信費支払 | M18: 通信事業者 | N18: 課税10% | O18: 適格 | Q18: =IF(AND(A18<>"",G18<>"",I18<>"",K18>0),"OK","")
A19: Prior | B19: 2025/05/31 | C19: JV-25012 | D19: 管理部 | E19: 共通 | F19: ADM | G19: 6200 | H19: 地代家賃 | I19: 1110 | J19: 現金及び預金 | K19: 2400000 | L19: オフィス賃料 | M19: 大家 | N19: 非課税 | O19: - | Q19: =IF(AND(A19<>"",G19<>"",I19<>"",K19>0),"OK","")
... A64: Current | B64: 2026/12/26 | C64: JV-26030 | D64: 管理部 | E64: 共通 | F64: FIN | G64: 1110 | H64: 現金及び預金 | I64: 7120 | J64: 受取配当金 | K64: 400000 | L64: 配当受領 | M64: 投資先 | N64: 非課税 | O64: - | Q64: =IF(AND(A64<>"",G64<>"",I64<>"",K64>0),"OK","")
Q65: =IF(AND(A65<>"",G65<>"",I65<>"",K65>0),"OK","")
Q66: =IF(AND(A66<>"",G66<>"",I66<>"",K66>0),"OK","")
Q67: =IF(AND(A67<>"",G67<>"",I67<>"",K67>0),"OK","")
Q68: =IF(AND(A68<>"",G68<>"",I68<>"",K68>0),"OK","")
Q69: =IF(AND(A69<>"",G69<>"",I69<>"",K69>0),"OK","")
Q70: =IF(AND(A70<>"",G70<>"",I70<>"",K70>0),"OK","")
Q71: =IF(AND(A71<>"",G71<>"",I71<>"",K71>0),"OK","")
Q72: =IF(AND(A72<>"",G72<>"",I72<>"",K72>0),"OK","")
Q73: =IF(AND(A73<>"",G73<>"",I73<>"",K73>0),"OK","")
Q74: =IF(AND(A74<>"",G74<>"",I74<>"",K74>0),"OK","")
Q75: =IF(AND(A75<>"",G75<>"",I75<>"",K75>0),"OK","")
Q76: =IF(AND(A76<>"",G76<>"",I76<>"",K76>0),"OK","")
... Q184: =IF(AND(A184<>"",G184<>"",I184<>"",K184>0),"OK","")

Sheet Overview
A1: B/S・P/L 複式簿記 分析テンプレート
A3: 用途 | B3: 勘定科目マスター → 仕訳入力 → 試算表 → 貸借対照表 → 損益計算書 → KPI分析 | F3: サイン規則
A4: 会計期間（前期） | B4: 2025 | C4: 会計期間（当期） | D4: 2026 | F4: 入力値は正数で入力、表示符号はマッピング側で制御
A5: 使い方 | B5: 1) COA_Masterで開始残高を確認 2) Journal_Inputに仕訳を追加 3) TB_Detail/BS_Form/PL_Form/KPI_Analysisを確認
F6: 重要
A7: 主要シート | B7: 内容 | C7: 入力/計算 | D7: 備考 | F7: ・B/Sは期末残高ベース
A8: COA_Master | B8: 勘定科目マスター（96科目、B/S・P/Lマッピング含む） | C8: 入力 | D8: 前期開始残高をここで管理 | F8: ・P/Lは期間損益ベース
A9: Journal_Input | B9: 複式仕訳入力。部門・セグメント・PJ付き | C9: 入力 | D9: 借方/貸方コード・金額を入力 | F9: ・BSとPLは複式仕訳から連動
A10: TB_Detail | B10: 試算表詳細。仕訳から借方/貸方/残高を自動集計 | C10: 計算 | D10: 前期/当期比較
A11: BS_Form | B11: 貸借対照表（上場会社風の詳細表示） | C11: 計算 | D11: 前期/当期/増減/構成比
A12: PL_Form | B12: 損益計算書（上場会社風の詳細表示） | C12: 計算 | D12: 前期/当期/増減/利益率
A13: KPI_Analysis | B13: 分析指標（流動比率、自己資本比率、ROA等） | C13: 計算 | D13: 後分析用
A14: BS_Map | B14: B/Sの中間集計 | C14: 計算 | D14: 補助シート
A15: PL_Map | B15: P/Lの中間集計 | C15: 計算 | D15: 補助シート
A16: SourceNotes | B16: 設計前提・会計ロジック・注意事項 | C16: 静的 | D16: 実装引き渡し用

Sheet SourceNotes
A1: SourceNotes / 設計前提
A3: 項目 | B3: 内容
A4: テンプレート目的 | B4: 実装着手用のB/S・P/L分析テンプレート。外部開示用の法定開示様式そのものではなく、複式簿記から分析可能な管理会計・開示寄りのレイアウト。
A5: 入力思想 | B5: Journal_Input に複式仕訳を入力し、TB_Detail で借方・貸方・残高を集計、BS/PL/KPIに反映。
A6: 勘定科目 | B6: 上場会社で一般的な表示区分を意識した詳細科目を収録。未使用科目は0のままでも可。
A7: B/S構造 | B7: 流動資産 / 固定資産 / 流動負債 / 固定負債 / 純資産の区分。投資その他の資産、OCI、非支配株主持分を含む。
A8: P/L構造 | B8: 純売上高 / 売上原価 / 売上総利益 / 販売費及び一般管理費 / 営業利益 / 営業外 / 特別損益 / 法人税等 / 当期純利益。
A9: 分析指標 | B9: 流動比率、当座比率、自己資本比率、D/E、純有利子負債、売上総利益率、営業利益率、経常利益率、当期純利益率、EBITDAマージン、ROA、ROE、総資産回転率、固定比率、インタレスト・カバレッジ。
A10: 符号ルール | B10: 入力は正数、表示上の符号・控除は Display_Sign とマッピングで制御。
A11: 前期/当期 | B11: 前期開始残高は COA_Master に入力。当期開始は前期末を自動引継ぎ。
A12: 注意 | B12: 税務提出用の正式帳票（青色申告決算書、収支内訳書、支払調書）とは別に管理すること。
A13: 利益剰余金の扱い | B13: この分析テンプレートでは、closing entry を Journal_Input に入力しなくても B/S が閉じるよう、利益剰余金表示行に前期/当期純利益を加算しています。
